[2022-11-14 02:00:46,037] {taskinstance.py:826} INFO - Dependencies all met for <TaskInstance: pyspark_bmi.load_data 2022-11-13T12:00:00+00:00 [queued]>
[2022-11-14 02:00:46,053] {taskinstance.py:826} INFO - Dependencies all met for <TaskInstance: pyspark_bmi.load_data 2022-11-13T12:00:00+00:00 [queued]>
[2022-11-14 02:00:46,053] {taskinstance.py:1017} INFO - 
--------------------------------------------------------------------------------
[2022-11-14 02:00:46,053] {taskinstance.py:1018} INFO - Starting attempt 1 of 1
[2022-11-14 02:00:46,053] {taskinstance.py:1019} INFO - 
--------------------------------------------------------------------------------
[2022-11-14 02:00:46,062] {taskinstance.py:1038} INFO - Executing <Task(PythonOperator): load_data> on 2022-11-13T12:00:00+00:00
[2022-11-14 02:00:46,067] {standard_task_runner.py:51} INFO - Started process 10387 to run task
[2022-11-14 02:00:46,071] {standard_task_runner.py:75} INFO - Running: ['airflow', 'tasks', 'run', 'pyspark_bmi', 'load_data', '2022-11-13T12:00:00+00:00', '--job-id', '6', '--pool', 'default_pool', '--raw', '--subdir', 'DAGS_FOLDER/pyspark_bmi.py', '--cfg-path', '/tmp/tmpkmmi47hf']
[2022-11-14 02:00:46,075] {standard_task_runner.py:76} INFO - Job 6: Subtask load_data
[2022-11-14 02:00:46,122] {logging_mixin.py:103} INFO - Running <TaskInstance: pyspark_bmi.load_data 2022-11-13T12:00:00+00:00 [running]> on host 6f0683b4a09b
[2022-11-14 02:00:46,168] {taskinstance.py:1232} INFO - Exporting the following env vars:
AIRFLOW_CTX_DAG_OWNER=airflow
AIRFLOW_CTX_DAG_ID=pyspark_bmi
AIRFLOW_CTX_TASK_ID=load_data
AIRFLOW_CTX_EXECUTION_DATE=2022-11-13T12:00:00+00:00
AIRFLOW_CTX_DAG_RUN_ID=backfill__2022-11-13T12:00:00+00:00
[2022-11-14 02:00:46,169] {taskinstance.py:1396} ERROR - No objects to concatenate
Traceback (most recent call last):
  File "/home/airflow/.local/lib/python3.6/site-packages/airflow/models/taskinstance.py", line 1086, in _run_raw_task
    self._prepare_and_execute_task_with_callbacks(context, task)
  File "/home/airflow/.local/lib/python3.6/site-packages/airflow/models/taskinstance.py", line 1260, in _prepare_and_execute_task_with_callbacks
    result = self._execute_task(context, task_copy)
  File "/home/airflow/.local/lib/python3.6/site-packages/airflow/models/taskinstance.py", line 1300, in _execute_task
    result = task_copy.execute(context=context)
  File "/home/airflow/.local/lib/python3.6/site-packages/airflow/operators/python.py", line 117, in execute
    return_value = self.execute_callable()
  File "/home/airflow/.local/lib/python3.6/site-packages/airflow/operators/python.py", line 128, in execute_callable
    return self.python_callable(*self.op_args, **self.op_kwargs)
  File "/opt/airflow/dags/pyspark_bmi.py", line 62, in load_data_to_postgresql
    df = pd.concat(pd.read_parquet(file) for file in data_dir.glob('*.parquet'))
  File "/home/airflow/.local/lib/python3.6/site-packages/pandas/core/reshape/concat.py", line 284, in concat
    sort=sort,
  File "/home/airflow/.local/lib/python3.6/site-packages/pandas/core/reshape/concat.py", line 331, in __init__
    raise ValueError("No objects to concatenate")
ValueError: No objects to concatenate
[2022-11-14 02:00:46,173] {taskinstance.py:1440} INFO - Marking task as FAILED. dag_id=pyspark_bmi, task_id=load_data, execution_date=20221113T120000, start_date=20221114T020046, end_date=20221114T020046
[2022-11-14 02:00:46,201] {local_task_job.py:118} INFO - Task exited with return code 1
[2022-11-14 03:37:06,604] {taskinstance.py:826} INFO - Dependencies all met for <TaskInstance: pyspark_bmi.load_data 2022-11-13T12:00:00+00:00 [queued]>
[2022-11-14 03:37:06,663] {taskinstance.py:826} INFO - Dependencies all met for <TaskInstance: pyspark_bmi.load_data 2022-11-13T12:00:00+00:00 [queued]>
[2022-11-14 03:37:06,663] {taskinstance.py:1017} INFO - 
--------------------------------------------------------------------------------
[2022-11-14 03:37:06,663] {taskinstance.py:1018} INFO - Starting attempt 1 of 1
[2022-11-14 03:37:06,663] {taskinstance.py:1019} INFO - 
--------------------------------------------------------------------------------
[2022-11-14 03:37:06,732] {taskinstance.py:1038} INFO - Executing <Task(PythonOperator): load_data> on 2022-11-13T12:00:00+00:00
[2022-11-14 03:37:06,737] {standard_task_runner.py:51} INFO - Started process 2095 to run task
[2022-11-14 03:37:06,740] {standard_task_runner.py:75} INFO - Running: ['airflow', 'tasks', 'run', 'pyspark_bmi', 'load_data', '2022-11-13T12:00:00+00:00', '--job-id', '5', '--pool', 'default_pool', '--raw', '--subdir', 'DAGS_FOLDER/pyspark_bmi.py', '--cfg-path', '/tmp/tmpahciv7df']
[2022-11-14 03:37:06,743] {standard_task_runner.py:76} INFO - Job 5: Subtask load_data
[2022-11-14 03:37:06,832] {logging_mixin.py:103} INFO - Running <TaskInstance: pyspark_bmi.load_data 2022-11-13T12:00:00+00:00 [running]> on host 676a9425fa5f
[2022-11-14 03:37:06,931] {taskinstance.py:1232} INFO - Exporting the following env vars:
AIRFLOW_CTX_DAG_OWNER=airflow
AIRFLOW_CTX_DAG_ID=pyspark_bmi
AIRFLOW_CTX_TASK_ID=load_data
AIRFLOW_CTX_EXECUTION_DATE=2022-11-13T12:00:00+00:00
AIRFLOW_CTX_DAG_RUN_ID=backfill__2022-11-13T12:00:00+00:00
[2022-11-14 03:37:07,497] {taskinstance.py:1396} ERROR - name 'psycopg2' is not defined
Traceback (most recent call last):
  File "/home/airflow/.local/lib/python3.6/site-packages/airflow/models/taskinstance.py", line 1086, in _run_raw_task
    self._prepare_and_execute_task_with_callbacks(context, task)
  File "/home/airflow/.local/lib/python3.6/site-packages/airflow/models/taskinstance.py", line 1260, in _prepare_and_execute_task_with_callbacks
    result = self._execute_task(context, task_copy)
  File "/home/airflow/.local/lib/python3.6/site-packages/airflow/models/taskinstance.py", line 1300, in _execute_task
    result = task_copy.execute(context=context)
  File "/home/airflow/.local/lib/python3.6/site-packages/airflow/operators/python.py", line 117, in execute
    return_value = self.execute_callable()
  File "/home/airflow/.local/lib/python3.6/site-packages/airflow/operators/python.py", line 128, in execute_callable
    return self.python_callable(*self.op_args, **self.op_kwargs)
  File "/opt/airflow/dags/pyspark_bmi.py", line 71, in load_data_to_postgresql
    conn = psycopg2.connect(
NameError: name 'psycopg2' is not defined
[2022-11-14 03:37:07,499] {taskinstance.py:1440} INFO - Marking task as FAILED. dag_id=pyspark_bmi, task_id=load_data, execution_date=20221113T120000, start_date=20221114T033706, end_date=20221114T033707
[2022-11-14 03:37:07,593] {local_task_job.py:118} INFO - Task exited with return code 1
